Workbook

Sheet SLP1
A1: ID | B1: G | C1: R | D1: B | E1: A | F1: S
A2: DUDN002 | B2: 5 | C2: 5 | D2: 5 | E2: 5 | F2: 5
A3: DUDN010 | B3: 5 | C3: 4 | D3: 5 | E3: 5 | F3: 5
A4: DUDN021 | B4: 4 | C4: 4 | D4: 5 | E4: 5 | F4: 4
A5: DUDN022 | B5: 5 | C5: 5 | D5: 5 | E5: 5 | F5: 5
A6: DUDN039 | B6: 5 | C6: 4 | D6: 5 | E6: 5 | F6: 5
A7: EUMCS01 | B7: 5 | C7: 5 | D7: 5 | E7: 5 | F7: 5
A8: EUMCS02 | B8: 5 | C8: 5 | D8: 4 | E8: 5 | F8: 5
A9: EUMCS04 | B9: 3 | C9: 2 | D9: 3 | E9: 3 | F9: 4
A10: EUMCS08 | B10: 4 | C10: 4 | D10: 5 | E10: 5 | F10: 4
A11: EUMCS10 | B11: 4 | C11: 4 | D11: 4 | E11: 5 | F11: 4
A12: EUMCS11 | B12: 5 | C12: 4 | D12: 5 | E12: 5 | F12: 5
A13: EUMCS12 | B13: 3 | C13: 3 | D13: 5 | E13: 5 | F13: 3
... A151: ST03 | B151: 3 | C151: 4 | D151: 4 | E151: 4 | F151: 3

Sheet SLP2
A1: ID | B1: G | C1: R | D1: B | E1: A | F1: S
A2: DUDN002 | B2: 5 | C2: 5 | D2: 5 | E2: 5 | F2: 5
A3: DUDN010 | B3: 5 | C3: 5 | D3: 5 | E3: 5 | F3: 4
A4: DUDN021 | B4: 5 | C4: 5 | D4: 5 | E4: 4 | F4: 4
A5: DUDN022 | B5: 5 | C5: 5 | D5: 5 | E5: 5 | F5: 5
A6: DUDN039 | B6: 5 | C6: 5 | D6: 5 | E6: 5 | F6: 4
A7: EUMCS01 | B7: 5 | C7: 5 | D7: 5 | E7: 4 | F7: 4
A8: EUMCS02 | B8: 5 | C8: 5 | D8: 5 | E8: 5 | F8: 5
A9: EUMCS04 | B9: 5 | C9: 5 | D9: 5 | E9: 5 | F9: 5
A10: EUMCS08 | B10: 5 | C10: 5 | D10: 5 | E10: 5 | F10: 5
A11: EUMCS10 | B11: 5 | C11: 5 | D11: 5 | E11: 4 | F11: 4
A12: EUMCS11 | B12: 3 | C12: 4 | D12: 4 | E12: 3 | F12: 2
A13: EUMCS12 | B13: 4 | C13: 4 | D13: 5 | E13: 5 | F13: 5
... A27: EUMCS33 | B27: 4 | C27: 4 | D27: 4 | E27: 5 | F27: 4
A28: EUMCS40 | B28: - | C28: - | D28: - | E28: - | F28: -
A29: EUMCS43 | B29: 4 | C29: 4 | D29: 3 | E29: 4 | F29: 4
A30: EUMCS44 | B30: 3 | C30: 4 | D30: 3 | E30: 3 | F30: 3
A31: EUMCS48 | B31: 4 | C31: 4 | D31: 4 | E31: 4 | F31: 4
A32: EUMCS49 | B32: 5 | C32: 5 | D32: 5 | E32: 5 | F32: 4
A33: EUMCS50 | B33: 4 | C33: 4 | D33: 5 | E33: 4 | F33: 4
A34: EUMCS51 | B34: 4 | C34: 4 | D34: 4 | E34: 4 | F34: 4
A35: EUMCS53 | B35: 3 | C35: 3 | D35: 4 | E35: 3 | F35: 3
A36: EUMCS55 | B36: 4 | C36: 3 | D36: 4 | E36: 3 | F36: 4
A37: EUMCS61 | B37: 2 | C37: 3 | D37: 2 | E37: 2 | F37: 2
A38: EUMCS62 | B38: 2 | C38: 2 | D38: 2 | E38: 2 | F38: 2
A39: EUMCS63 | B39: 3 | C39: 2 | D39: 2 | E39: 3 | F39: 2
A40: EUMCS71 | B40: 4 | C40: 4 | D40: 5 | E40: 5 | F40: 4
... A117: REA013 | B117: 1 | C117: 1 | D117: 1 | E117: 1 | F117: 1
A118: REA016 | B118: - | C118: - | D118: - | E118: - | F118: -
A119: REA020 | B119: 2 | C119: 1 | D119: 2 | E119: 2 | F119: 1
A120: REA021 | B120: 3 | C120: 2 | D120: 2 | E120: 2 | F120: 2
A121: REA022 | B121: 4 | C121: 4 | D121: 4 | E121: 4 | F121: 3
A122: REA023 | B122: 3 | C122: 2 | D122: 3 | E122: 3 | F122: 2
A123: REA026 | B123: 2 | C123: 3 | D123: 2 | E123: 2 | F123: 1
A124: REA027 | B124: 2 | C124: 1 | D124: 1 | E124: 1 | F124: 3
A125: REC001 | B125: 1 | C125: 1 | D125: 1 | E125: 1 | F125: 1
A126: EUMCS82 | B126: 4 | C126: 4 | D126: 5 | E126: 5 | F126: 4
A127: H040 | B127: 5 | C127: 5 | D127: 4 | E127: 4 | F127: 5
A128: NRC36 | B128: 4 | C128: 4 | D128: 5 | E128: 5 | F128: 4
A129: V022N | B129: 4 | C129: 4 | D129: 4 | E129: 4 | F129: 4
...

Sheet SLP3
A1: ID | B1: G | C1: R | D1: B | E1: A | F1: S
A2: DUDN002 | B2: 5 | C2: 5 | D2: 5 | E2: 5 | F2: 5
A3: DUDN010 | B3: 5 | C3: 5 | D3: 5 | E3: 5 | F3: 4
A4: DUDN021 | B4: 4 | C4: 3 | D4: 5 | E4: 4 | F4: 5
A5: DUDN022 | B5: 5 | C5: 5 | D5: 5 | E5: 4 | F5: 5
A6: DUDN039 | B6: 5 | C6: 4 | D6: 5 | E6: 5 | F6: 5
A7: EUMCS01 | B7: 5 | C7: 4 | D7: 5 | E7: 5 | F7: 5
A8: EUMCS02 | B8: 5 | C8: 5 | D8: 4 | E8: 3 | F8: 5
A9: EUMCS04 | B9: 2 | C9: 2 | D9: 3 | E9: 4 | F9: 5
A10: EUMCS08 | B10: 4 | C10: 4 | D10: 5 | E10: 5 | F10: 3
A11: EUMCS10 | B11: 3 | C11: 3 | D11: 4 | E11: 5 | F11: 4
A12: EUMCS11 | B12: 3 | C12: 3 | D12: 5 | E12: 5 | F12: 4
A13: EUMCS12 | B13: 4 | C13: 4 | D13: 5 | E13: 5 | F13: 5
... A151: ST03 | B151: 3 | C151: 4 | D151: 4 | E151: 4 | F151: 3

Sheet SLPall
A1: ID | B1: G | C1: R | D1: B | E1: A | F1: S
A2: DUDN002 | B2: =ROUND(AVERAGE('SLP1'!B2, 'SLP2'!B2, 'SLP3'!B2), 3) -> 5 | C2: =ROUND(AVERAGE('SLP1'!C2, 'SLP2'!C2, 'SLP3'!C2), 3) -> 5 | D2: =ROUND(AVERAGE('SLP1'!D2, 'SLP2'!D2, 'SLP3'!D2), 3) -> 5 | E2: =ROUND(AVERAGE('SLP1'!E2, 'SLP2'!E2, 'SLP3'!E2), 3) -> 5 | F2: =ROUND(AVERAGE('SLP1'!F2, 'SLP2'!F2, 'SLP3'!F2), 3) -> 5
A3: DUDN010 | B3: =ROUND(AVERAGE('SLP1'!B3, 'SLP2'!B3, 'SLP3'!B3), 3) -> 5 | C3: =ROUND(AVERAGE('SLP1'!C3, 'SLP2'!C3, 'SLP3'!C3), 3) -> 4.667 | D3: =ROUND(AVERAGE('SLP1'!D3, 'SLP2'!D3, 'SLP3'!D3), 3) -> 5 | E3: =ROUND(AVERAGE('SLP1'!E3, 'SLP2'!E3, 'SLP3'!E3), 3) -> 5 | F3: =ROUND(AVERAGE('SLP1'!F3, 'SLP2'!F3, 'SLP3'!F3), 3) -> 4.333
A4: DUDN021 | B4: =ROUND(AVERAGE('SLP1'!B4, 'SLP2'!B4, 'SLP3'!B4), 3) -> 4.333 | C4: =ROUND(AVERAGE('SLP1'!C4, 'SLP2'!C4, 'SLP3'!C4), 3) -> 4 | D4: =ROUND(AVERAGE('SLP1'!D4, 'SLP2'!D4, 'SLP3'!D4), 3) -> 5 | E4: =ROUND(AVERAGE('SLP1'!E4, 'SLP2'!E4, 'SLP3'!E4), 3) -> 4.333 | F4: =ROUND(AVERAGE('SLP1'!F4, 'SLP2'!F4, 'SLP3'!F4), 3) -> 4.333
A5: DUDN022 | B5: =ROUND(AVERAGE('SLP1'!B5, 'SLP2'!B5, 'SLP3'!B5), 3) -> 5 | C5: =ROUND(AVERAGE('SLP1'!C5, 'SLP2'!C5, 'SLP3'!C5), 3) -> 5 | D5: =ROUND(AVERAGE('SLP1'!D5, 'SLP2'!D5, 'SLP3'!D5), 3) -> 5 | E5: =ROUND(AVERAGE('SLP1'!E5, 'SLP2'!E5, 'SLP3'!E5), 3) -> 4.667 | F5: =ROUND(AVERAGE('SLP1'!F5, 'SLP2'!F5, 'SLP3'!F5), 3) -> 5
A6: DUDN039 | B6: =ROUND(AVERAGE('SLP1'!B6, 'SLP2'!B6, 'SLP3'!B6), 3) -> 5 | C6: =ROUND(AVERAGE('SLP1'!C6, 'SLP2'!C6, 'SLP3'!C6), 3) -> 4.333 | D6: =ROUND(AVERAGE('SLP1'!D6, 'SLP2'!D6, 'SLP3'!D6), 3) -> 5 | E6: =ROUND(AVERAGE('SLP1'!E6, 'SLP2'!E6, 'SLP3'!E6), 3) -> 5 | F6: =ROUND(AVERAGE('SLP1'!F6, 'SLP2'!F6, 'SLP3'!F6), 3) -> 4.667
A7: EUMCS01 | B7: =ROUND(AVERAGE('SLP1'!B7, 'SLP2'!B7, 'SLP3'!B7), 3) -> 5 | C7: =ROUND(AVERAGE('SLP1'!C7, 'SLP2'!C7, 'SLP3'!C7), 3) -> 4.667 | D7: =ROUND(AVERAGE('SLP1'!D7, 'SLP2'!D7, 'SLP3'!D7), 3) -> 5 | E7: =ROUND(AVERAGE('SLP1'!E7, 'SLP2'!E7, 'SLP3'!E7), 3) -> 4.667 | F7: =ROUND(AVERAGE('SLP1'!F7, 'SLP2'!F7, 'SLP3'!F7), 3) -> 4.667
A8: EUMCS02 | B8: =ROUND(AVERAGE('SLP1'!B8, 'SLP2'!B8, 'SLP3'!B8), 3) -> 5 | C8: =ROUND(AVERAGE('SLP1'!C8, 'SLP2'!C8, 'SLP3'!C8), 3) -> 5 | D8: =ROUND(AVERAGE('SLP1'!D8, 'SLP2'!D8, 'SLP3'!D8), 3) -> 4.333 | E8: =ROUND(AVERAGE('SLP1'!E8, 'SLP2'!E8, 'SLP3'!E8), 3) -> 4.333 | F8: =ROUND(AVERAGE('SLP1'!F8, 'SLP2'!F8, 'SLP3'!F8), 3) -> 5
A9: EUMCS04 | B9: =ROUND(AVERAGE('SLP1'!B9, 'SLP2'!B9, 'SLP3'!B9), 3) -> 3.333 | C9: =ROUND(AVERAGE('SLP1'!C9, 'SLP2'!C9, 'SLP3'!C9), 3) -> 3 | D9: =ROUND(AVERAGE('SLP1'!D9, 'SLP2'!D9, 'SLP3'!D9), 3) -> 3.667 | E9: =ROUND(AVERAGE('SLP1'!E9, 'SLP2'!E9, 'SLP3'!E9), 3) -> 4 | F9: =ROUND(AVERAGE('SLP1'!F9, 'SLP2'!F9, 'SLP3'!F9), 3) -> 4.667
A10: EUMCS08 | B10: =ROUND(AVERAGE('SLP1'!B10, 'SLP2'!B10, 'SLP3'!B10), 3) -> 4.333 | C10: =ROUND(AVERAGE('SLP1'!C10, 'SLP2'!C10, 'SLP3'!C10), 3) -> 4.333 | D10: =ROUND(AVERAGE('SLP1'!D10, 'SLP2'!D10, 'SLP3'!D10), 3) -> 5 | E10: =ROUND(AVERAGE('SLP1'!E10, 'SLP2'!E10, 'SLP3'!E10), 3) -> 5 | F10: =ROUND(AVERAGE('SLP1'!F10, 'SLP2'!F10, 'SLP3'!F10), 3) -> 4
A11: EUMCS10 | B11: =ROUND(AVERAGE('SLP1'!B11, 'SLP2'!B11, 'SLP3'!B11), 3) -> 4 | C11: =ROUND(AVERAGE('SLP1'!C11, 'SLP2'!C11, 'SLP3'!C11), 3) -> 4 | D11: =ROUND(AVERAGE('SLP1'!D11, 'SLP2'!D11, 'SLP3'!D11), 3) -> 4.333 | E11: =ROUND(AVERAGE('SLP1'!E11, 'SLP2'!E11, 'SLP3'!E11), 3) -> 4.667 | F11: =ROUND(AVERAGE('SLP1'!F11, 'SLP2'!F11, 'SLP3'!F11), 3) -> 4
A12: EUMCS11 | B12: =ROUND(AVERAGE('SLP1'!B12, 'SLP2'!B12, 'SLP3'!B12), 3) -> 3.667 | C12: =ROUND(AVERAGE('SLP1'!C12, 'SLP2'!C12, 'SLP3'!C12), 3) -> 3.667 | D12: =ROUND(AVERAGE('SLP1'!D12, 'SLP2'!D12, 'SLP3'!D12), 3) -> 4.667 | E12: =ROUND(AVERAGE('SLP1'!E12, 'SLP2'!E12, 'SLP3'!E12), 3) -> 4.333 | F12: =ROUND(AVERAGE('SLP1'!F12, 'SLP2'!F12, 'SLP3'!F12), 3) -> 3.667
A13: EUMCS12 | B13: =ROUND(AVERAGE('SLP1'!B13, 'SLP2'!B13, 'SLP3'!B13), 3) -> 3.667 | C13: =ROUND(AVERAGE('SLP1'!C13, 'SLP2'!C13, 'SLP3'!C13), 3) -> 3.667 | D13: =ROUND(AVERAGE('SLP1'!D13, 'SLP2'!D13, 'SLP3'!D13), 3) -> 5 | E13: =ROUND(AVERAGE('SLP1'!E13, 'SLP2'!E13, 'SLP3'!E13), 3) -> 5 | F13: =ROUND(AVERAGE('SLP1'!F13, 'SLP2'!F13, 'SLP3'!F13), 3) -> 4.333
... A151: ST03 | B151: =ROUND(AVERAGE('SLP1'!B151, 'SLP2'!B151, 'SLP3'!B151), 3) -> 3.333 | C151: =ROUND(AVERAGE('SLP1'!C151, 'SLP2'!C151, 'SLP3'!C151), 3) -> 3.667 | D151: =ROUND(AVERAGE('SLP1'!D151, 'SLP2'!D151, 'SLP3'!D151), 3) -> 3.667 | E151: =ROUND(AVERAGE('SLP1'!E151, 'SLP2'!E151, 'SLP3'!E151), 3) -> 3.667 | F151: =ROUND(AVERAGE('SLP1'!F151, 'SLP2'!F151, 'SLP3'!F151), 3) -> 3.333
